Internal Server Error: /plant/create/
Traceback (most recent call last):
  File "C:\Users\user\Documents\Python\MaintenancePlannerEdition1\venv\Lib\site-packages\django\core\handlers\exception.py", line 55, in inner
    response = get_response(request)
               ^^^^^^^^^^^^^^^^^^^^^
  File "C:\Users\user\Documents\Python\MaintenancePlannerEdition1\venv\Lib\site-packages\django\core\handlers\base.py", line 197, in _get_response
    response = wrapped_callback(request, *callback_args, **callback_kwargs)
               ^^^^^^^^^^^^^^^^^^^^^^^^^^^^^^^^^^^^^^^^^^^^^^^^^^^^^^^^^^^^
  File "C:\Users\user\Documents\Python\MaintenancePlannerEdition1\venv\Lib\site-packages\django\views\generic\base.py", line 104, in view
    return self.dispatch(request, *args, **kwargs)
           ^^^^^^^^^^^^^^^^^^^^^^^^^^^^^^^^^^^^^^^
  File "C:\Users\user\Documents\Python\MaintenancePlannerEdition1\venv\Lib\site-packages\django\contrib\auth\mixins.py", line 73, in dispatch
    return super().dispatch(request, *args, **kwargs)
           ^^^^^^^^^^^^^^^^^^^^^^^^^^^^^^^^^^^^^^^^^^
  File "C:\Users\user\Documents\Python\MaintenancePlannerEdition1\venv\Lib\site-packages\django\contrib\auth\mixins.py", line 107, in dispatch
    if not self.has_permission():
           ^^^^^^^^^^^^^^^^^^^^^
  File "C:\Users\user\Documents\Python\MaintenancePlannerEdition1\venv\Lib\site-packages\django\contrib\auth\mixins.py", line 103, in has_permission
    perms = self.get_permission_required()
            ^^^^^^^^^^^^^^^^^^^^^^^^^^^^^^
  File "C:\Users\user\Documents\Python\MaintenancePlannerEdition1\venv\Lib\site-packages\django\contrib\auth\mixins.py", line 87, in get_permission_required
    raise ImproperlyConfigured(
django.core.exceptions.ImproperlyConfigured: PlantCreateView is missing the permission_required attribute. Define PlantCreateView.permission_required, or override PlantCreateView.get_permission_required().
"GET /plant/create/ HTTP/1.1" 500 88302
Internal Server Error: /plant/create/
Traceback (most recent call last):
  File "C:\Users\user\Documents\Python\MaintenancePlannerEdition1\venv\Lib\site-packages\django\core\handlers\exception.py", line 55, in inner
    response = get_response(request)
               ^^^^^^^^^^^^^^^^^^^^^
  File "C:\Users\user\Documents\Python\MaintenancePlannerEdition1\venv\Lib\site-packages\django\core\handlers\base.py", line 197, in _get_response
    response = wrapped_callback(request, *callback_args, **callback_kwargs)
               ^^^^^^^^^^^^^^^^^^^^^^^^^^^^^^^^^^^^^^^^^^^^^^^^^^^^^^^^^^^^
  File "C:\Users\user\Documents\Python\MaintenancePlannerEdition1\venv\Lib\site-packages\django\views\generic\base.py", line 104, in view
    return self.dispatch(request, *args, **kwargs)
           ^^^^^^^^^^^^^^^^^^^^^^^^^^^^^^^^^^^^^^^
  File "C:\Users\user\Documents\Python\MaintenancePlannerEdition1\venv\Lib\site-packages\django\contrib\auth\mixins.py", line 73, in dispatch
    return super().dispatch(request, *args, **kwargs)
           ^^^^^^^^^^^^^^^^^^^^^^^^^^^^^^^^^^^^^^^^^^
  File "C:\Users\user\Documents\Python\MaintenancePlannerEdition1\venv\Lib\site-packages\django\contrib\auth\mixins.py", line 107, in dispatch
    if not self.has_permission():
           ^^^^^^^^^^^^^^^^^^^^^
  File "C:\Users\user\Documents\Python\MaintenancePlannerEdition1\venv\Lib\site-packages\django\contrib\auth\mixins.py", line 103, in has_permission
    perms = self.get_permission_required()
            ^^^^^^^^^^^^^^^^^^^^^^^^^^^^^^
  File "C:\Users\user\Documents\Python\MaintenancePlannerEdition1\venv\Lib\site-packages\django\contrib\auth\mixins.py", line 87, in get_permission_required
    raise ImproperlyConfigured(
django.core.exceptions.ImproperlyConfigured: PlantCreateView is missing the permission_required attribute. Define PlantCreateView.permission_required, or override PlantCreateView.get_permission_required().
"GET /plant/create/ HTTP/1.1" 500 88450
