Internal Server Error: /plant/create/
Traceback (most recent call last):
  File "C:\Users\user\Documents\Python\MaintenancePlannerEdition1\venv\Lib\site-packages\django\core\handlers\exception.py", line 55, in inner
    response = get_response(request)
               ^^^^^^^^^^^^^^^^^^^^^
  File "C:\Users\user\Documents\Python\MaintenancePlannerEdition1\venv\Lib\site-packages\django\core\handlers\base.py", line 197, in _get_response
    response = wrapped_callback(request, *callback_args, **callback_kwargs)
               ^^^^^^^^^^^^^^^^^^^^^^^^^^^^^^^^^^^^^^^^^^^^^^^^^^^^^^^^^^^^
  File "C:\Users\user\Documents\Python\MaintenancePlannerEdition1\venv\Lib\site-packages\django\views\generic\base.py", line 104, in view
    return self.dispatch(request, *args, **kwargs)
           ^^^^^^^^^^^^^^^^^^^^^^^^^^^^^^^^^^^^^^^
  File "C:\Users\user\Documents\Python\MaintenancePlannerEdition1\venv\Lib\site-packages\django\contrib\auth\mixins.py", line 73, in dispatch
    return super().dispatch(request, *args, **kwargs)
           ^^^^^^^^^^^^^^^^^^^^^^^^^^^^^^^^^^^^^^^^^^
  File "C:\Users\user\Documents\Python\MaintenancePlannerEdition1\venv\Lib\site-packages\django\contrib\auth\mixins.py", line 107, in dispatch
    if not self.has_permission():
           ^^^^^^^^^^^^^^^^^^^^^
  File "C:\Users\user\Documents\Python\MaintenancePlannerEdition1\venv\Lib\site-packages\django\contrib\auth\mixins.py", line 103, in has_permission
    perms = self.get_permission_required()
            ^^^^^^^^^^^^^^^^^^^^^^^^^^^^^^
  File "C:\Users\user\Documents\Python\MaintenancePlannerEdition1\venv\Lib\site-packages\django\contrib\auth\mixins.py", line 87, in get_permission_required
    raise ImproperlyConfigured(
django.core.exceptions.ImproperlyConfigured: PlantCreateView is missing the permission_required attribute. Define PlantCreateView.permission_required, or override PlantCreateView.get_permission_required().
"GET /plant/create/ HTTP/1.1" 500 88302
Internal Server Error: /plant/create/
Traceback (most recent call last):
  File "C:\Users\user\Documents\Python\MaintenancePlannerEdition1\venv\Lib\site-packages\django\core\handlers\exception.py", line 55, in inner
    response = get_response(request)
               ^^^^^^^^^^^^^^^^^^^^^
  File "C:\Users\user\Documents\Python\MaintenancePlannerEdition1\venv\Lib\site-packages\django\core\handlers\base.py", line 197, in _get_response
    response = wrapped_callback(request, *callback_args, **callback_kwargs)
               ^^^^^^^^^^^^^^^^^^^^^^^^^^^^^^^^^^^^^^^^^^^^^^^^^^^^^^^^^^^^
  File "C:\Users\user\Documents\Python\MaintenancePlannerEdition1\venv\Lib\site-packages\django\views\generic\base.py", line 104, in view
    return self.dispatch(request, *args, **kwargs)
           ^^^^^^^^^^^^^^^^^^^^^^^^^^^^^^^^^^^^^^^
  File "C:\Users\user\Documents\Python\MaintenancePlannerEdition1\venv\Lib\site-packages\django\contrib\auth\mixins.py", line 73, in dispatch
    return super().dispatch(request, *args, **kwargs)
           ^^^^^^^^^^^^^^^^^^^^^^^^^^^^^^^^^^^^^^^^^^
  File "C:\Users\user\Documents\Python\MaintenancePlannerEdition1\venv\Lib\site-packages\django\contrib\auth\mixins.py", line 107, in dispatch
    if not self.has_permission():
           ^^^^^^^^^^^^^^^^^^^^^
  File "C:\Users\user\Documents\Python\MaintenancePlannerEdition1\venv\Lib\site-packages\django\contrib\auth\mixins.py", line 103, in has_permission
    perms = self.get_permission_required()
            ^^^^^^^^^^^^^^^^^^^^^^^^^^^^^^
  File "C:\Users\user\Documents\Python\MaintenancePlannerEdition1\venv\Lib\site-packages\django\contrib\auth\mixins.py", line 87, in get_permission_required
    raise ImproperlyConfigured(
django.core.exceptions.ImproperlyConfigured: PlantCreateView is missing the permission_required attribute. Define PlantCreateView.permission_required, or override PlantCreateView.get_permission_required().
"GET /plant/create/ HTTP/1.1" 500 88450
Internal Server Error: /user/delete/3/
Traceback (most recent call last):
  File "C:\Users\user\Documents\Python\MaintenancePlannerEdition1\venv\Lib\site-packages\django\core\handlers\exception.py", line 55, in inner
    response = get_response(request)
               ^^^^^^^^^^^^^^^^^^^^^
  File "C:\Users\user\Documents\Python\MaintenancePlannerEdition1\venv\Lib\site-packages\django\core\handlers\base.py", line 220, in _get_response
    response = response.render()
               ^^^^^^^^^^^^^^^^^
  File "C:\Users\user\Documents\Python\MaintenancePlannerEdition1\venv\Lib\site-packages\django\template\response.py", line 114, in render
    self.content = self.rendered_content
                   ^^^^^^^^^^^^^^^^^^^^^
  File "C:\Users\user\Documents\Python\MaintenancePlannerEdition1\venv\Lib\site-packages\django\template\response.py", line 90, in rendered_content
    template = self.resolve_template(self.template_name)
               ^^^^^^^^^^^^^^^^^^^^^^^^^^^^^^^^^^^^^^^^^
  File "C:\Users\user\Documents\Python\MaintenancePlannerEdition1\venv\Lib\site-packages\django\template\response.py", line 72, in resolve_template
    return select_template(template, using=self.using)
           ^^^^^^^^^^^^^^^^^^^^^^^^^^^^^^^^^^^^^^^^^^^
  File "C:\Users\user\Documents\Python\MaintenancePlannerEdition1\venv\Lib\site-packages\django\template\loader.py", line 47, in select_template
    raise TemplateDoesNotExist(", ".join(template_name_list), chain=chain)
django.template.exceptions.TemplateDoesNotExist: accounts/appuser_confirm_delete.html
"GET /user/delete/3/ HTTP/1.1" 500 89418
Internal Server Error: /
"GET / HTTP/1.1" 500 137
Internal Server Error: /favicon.ico
"GET /favicon.ico HTTP/1.1" 500 137
Internal Server Error: /user/password-reset/confirm/Mw/set-password/
Traceback (most recent call last):
  File "C:\Users\user\Documents\Python\MaintenancePlannerEdition1\venv\Lib\site-packages\django\core\handlers\exception.py", line 55, in inner
    response = get_response(request)
               ^^^^^^^^^^^^^^^^^^^^^
  File "C:\Users\user\Documents\Python\MaintenancePlannerEdition1\venv\Lib\site-packages\django\core\handlers\base.py", line 197, in _get_response
    response = wrapped_callback(request, *callback_args, **callback_kwargs)
               ^^^^^^^^^^^^^^^^^^^^^^^^^^^^^^^^^^^^^^^^^^^^^^^^^^^^^^^^^^^^
  File "C:\Users\user\Documents\Python\MaintenancePlannerEdition1\venv\Lib\site-packages\django\views\generic\base.py", line 104, in view
    return self.dispatch(request, *args, **kwargs)
           ^^^^^^^^^^^^^^^^^^^^^^^^^^^^^^^^^^^^^^^
  File "C:\Users\user\Documents\Python\MaintenancePlannerEdition1\venv\Lib\site-packages\django\utils\decorators.py", line 46, in _wrapper
    return bound_method(*args, **kwargs)
           ^^^^^^^^^^^^^^^^^^^^^^^^^^^^^
  File "C:\Users\user\Documents\Python\MaintenancePlannerEdition1\venv\Lib\site-packages\django\views\decorators\debug.py", line 92, in sensitive_post_parameters_wrapper
    return view(request, *args, **kwargs)
           ^^^^^^^^^^^^^^^^^^^^^^^^^^^^^^
  File "C:\Users\user\Documents\Python\MaintenancePlannerEdition1\venv\Lib\site-packages\django\utils\decorators.py", line 46, in _wrapper
    return bound_method(*args, **kwargs)
           ^^^^^^^^^^^^^^^^^^^^^^^^^^^^^
  File "C:\Users\user\Documents\Python\MaintenancePlannerEdition1\venv\Lib\site-packages\django\views\decorators\cache.py", line 62, in _wrapper_view_func
    response = view_func(request, *args, **kwargs)
               ^^^^^^^^^^^^^^^^^^^^^^^^^^^^^^^^^^^
  File "C:\Users\user\Documents\Python\MaintenancePlannerEdition1\venv\Lib\site-packages\django\contrib\auth\views.py", line 295, in dispatch
    return super().dispatch(*args, **kwargs)
           ^^^^^^^^^^^^^^^^^^^^^^^^^^^^^^^^^
  File "C:\Users\user\Documents\Python\MaintenancePlannerEdition1\venv\Lib\site-packages\django\views\generic\base.py", line 143, in dispatch
    return handler(request, *args, **kwargs)
           ^^^^^^^^^^^^^^^^^^^^^^^^^^^^^^^^^
  File "C:\Users\user\Documents\Python\MaintenancePlannerEdition1\venv\Lib\site-packages\django\views\generic\edit.py", line 153, in post
    return self.form_valid(form)
           ^^^^^^^^^^^^^^^^^^^^^
  File "C:\Users\user\Documents\Python\MaintenancePlannerEdition1\venv\Lib\site-packages\django\contrib\auth\views.py", line 336, in form_valid
    return super().form_valid(form)
           ^^^^^^^^^^^^^^^^^^^^^^^^
  File "C:\Users\user\Documents\Python\MaintenancePlannerEdition1\venv\Lib\site-packages\django\views\generic\edit.py", line 65, in form_valid
    return HttpResponseRedirect(self.get_success_url())
                                ^^^^^^^^^^^^^^^^^^^^^^
  File "C:\Users\user\Documents\Python\MaintenancePlannerEdition1\venv\Lib\site-packages\django\views\generic\edit.py", line 59, in get_success_url
    if not self.success_url:
  File "C:\Users\user\Documents\Python\MaintenancePlannerEdition1\venv\Lib\site-packages\django\utils\functional.py", line 149, in __wrapper__
    res = func(*self.__args, **self.__kw)
          ^^^^^^^^^^^^^^^^^^^^^^^^^^^^^^^
  File "C:\Users\user\Documents\Python\MaintenancePlannerEdition1\venv\Lib\site-packages\django\urls\base.py", line 88, in reverse
    return resolver._reverse_with_prefix(view, prefix, *args, **kwargs)
           ^^^^^^^^^^^^^^^^^^^^^^^^^^^^^^^^^^^^^^^^^^^^^^^^^^^^^^^^^^^^
  File "C:\Users\user\Documents\Python\MaintenancePlannerEdition1\venv\Lib\site-packages\django\urls\resolvers.py", line 828, in _reverse_with_prefix
    raise NoReverseMatch(msg)
django.urls.exceptions.NoReverseMatch: Reverse for 'password_reset_complete' not found. 'password_reset_complete' is not a valid view function or pattern name.
"POST /user/password-reset/confirm/Mw/set-password/ HTTP/1.1" 500 135262
Internal Server Error: /user/password-reset/
Traceback (most recent call last):
  File "C:\Users\user\Documents\Python\MaintenancePlannerEdition1\venv\Lib\site-packages\django\core\handlers\exception.py", line 55, in inner
    response = get_response(request)
               ^^^^^^^^^^^^^^^^^^^^^
  File "C:\Users\user\Documents\Python\MaintenancePlannerEdition1\venv\Lib\site-packages\django\core\handlers\base.py", line 197, in _get_response
    response = wrapped_callback(request, *callback_args, **callback_kwargs)
               ^^^^^^^^^^^^^^^^^^^^^^^^^^^^^^^^^^^^^^^^^^^^^^^^^^^^^^^^^^^^
  File "C:\Users\user\Documents\Python\MaintenancePlannerEdition1\venv\Lib\site-packages\django\views\generic\base.py", line 104, in view
    return self.dispatch(request, *args, **kwargs)
           ^^^^^^^^^^^^^^^^^^^^^^^^^^^^^^^^^^^^^^^
  File "C:\Users\user\Documents\Python\MaintenancePlannerEdition1\venv\Lib\site-packages\django\utils\decorators.py", line 46, in _wrapper
    return bound_method(*args, **kwargs)
           ^^^^^^^^^^^^^^^^^^^^^^^^^^^^^
  File "C:\Users\user\Documents\Python\MaintenancePlannerEdition1\venv\Lib\site-packages\django\utils\decorators.py", line 134, in _wrapper_view
    response = view_func(request, *args, **kwargs)
               ^^^^^^^^^^^^^^^^^^^^^^^^^^^^^^^^^^^
  File "C:\Users\user\Documents\Python\MaintenancePlannerEdition1\venv\Lib\site-packages\django\contrib\auth\views.py", line 242, in dispatch
    return super().dispatch(*args, **kwargs)
           ^^^^^^^^^^^^^^^^^^^^^^^^^^^^^^^^^
  File "C:\Users\user\Documents\Python\MaintenancePlannerEdition1\venv\Lib\site-packages\django\views\generic\base.py", line 143, in dispatch
    return handler(request, *args, **kwargs)
           ^^^^^^^^^^^^^^^^^^^^^^^^^^^^^^^^^
  File "C:\Users\user\Documents\Python\MaintenancePlannerEdition1\venv\Lib\site-packages\django\views\generic\edit.py", line 153, in post
    return self.form_valid(form)
           ^^^^^^^^^^^^^^^^^^^^^
  File "C:\Users\user\Documents\Python\MaintenancePlannerEdition1\venv\Lib\site-packages\django\contrib\auth\views.py", line 255, in form_valid
    form.save(**opts)
  File "C:\Users\user\Documents\Python\MaintenancePlannerEdition1\venv\Lib\site-packages\django\contrib\auth\forms.py", line 368, in save
    self.send_mail(
  File "C:\Users\user\Documents\Python\MaintenancePlannerEdition1\venv\Lib\site-packages\django\contrib\auth\forms.py", line 302, in send_mail
    body = loader.render_to_string(email_template_name, context)
           ^^^^^^^^^^^^^^^^^^^^^^^^^^^^^^^^^^^^^^^^^^^^^^^^^^^^^
  File "C:\Users\user\Documents\Python\MaintenancePlannerEdition1\venv\Lib\site-packages\django\template\loader.py", line 62, in render_to_string
    return template.render(context, request)
           ^^^^^^^^^^^^^^^^^^^^^^^^^^^^^^^^^
  File "C:\Users\user\Documents\Python\MaintenancePlannerEdition1\venv\Lib\site-packages\django\template\backends\django.py", line 61, in render
    return self.template.render(context)
           ^^^^^^^^^^^^^^^^^^^^^^^^^^^^^
  File "C:\Users\user\Documents\Python\MaintenancePlannerEdition1\venv\Lib\site-packages\django\template\base.py", line 175, in render
    return self._render(context)
           ^^^^^^^^^^^^^^^^^^^^^
  File "C:\Users\user\Documents\Python\MaintenancePlannerEdition1\venv\Lib\site-packages\django\template\base.py", line 167, in _render
    return self.nodelist.render(context)
           ^^^^^^^^^^^^^^^^^^^^^^^^^^^^^
  File "C:\Users\user\Documents\Python\MaintenancePlannerEdition1\venv\Lib\site-packages\django\template\base.py", line 1005, in render
    return SafeString("".join([node.render_annotated(context) for node in self]))
                              ^^^^^^^^^^^^^^^^^^^^^^^^^^^^^^^^^^^^^^^^^^^^^^^^^
  File "C:\Users\user\Documents\Python\MaintenancePlannerEdition1\venv\Lib\site-packages\django\template\base.py", line 1005, in <listcomp>
    return SafeString("".join([node.render_annotated(context) for node in self]))
                               ^^^^^^^^^^^^^^^^^^^^^^^^^^^^^^
  File "C:\Users\user\Documents\Python\MaintenancePlannerEdition1\venv\Lib\site-packages\django\template\base.py", line 966, in render_annotated
    return self.render(context)
           ^^^^^^^^^^^^^^^^^^^^
  File "C:\Users\user\Documents\Python\MaintenancePlannerEdition1\venv\Lib\site-packages\django\template\defaulttags.py", line 52, in render
    output = self.nodelist.render(context)
             ^^^^^^^^^^^^^^^^^^^^^^^^^^^^^
  File "C:\Users\user\Documents\Python\MaintenancePlannerEdition1\venv\Lib\site-packages\django\template\base.py", line 1005, in render
    return SafeString("".join([node.render_annotated(context) for node in self]))
                              ^^^^^^^^^^^^^^^^^^^^^^^^^^^^^^^^^^^^^^^^^^^^^^^^^
  File "C:\Users\user\Documents\Python\MaintenancePlannerEdition1\venv\Lib\site-packages\django\template\base.py", line 1005, in <listcomp>
    return SafeString("".join([node.render_annotated(context) for node in self]))
                               ^^^^^^^^^^^^^^^^^^^^^^^^^^^^^^
  File "C:\Users\user\Documents\Python\MaintenancePlannerEdition1\venv\Lib\site-packages\django\template\base.py", line 966, in render_annotated
    return self.render(context)
           ^^^^^^^^^^^^^^^^^^^^
  File "C:\Users\user\Documents\Python\MaintenancePlannerEdition1\venv\Lib\site-packages\django\template\loader_tags.py", line 54, in render
    result = self.nodelist.render(context)
             ^^^^^^^^^^^^^^^^^^^^^^^^^^^^^
  File "C:\Users\user\Documents\Python\MaintenancePlannerEdition1\venv\Lib\site-packages\django\template\base.py", line 1005, in render
    return SafeString("".join([node.render_annotated(context) for node in self]))
                              ^^^^^^^^^^^^^^^^^^^^^^^^^^^^^^^^^^^^^^^^^^^^^^^^^
  File "C:\Users\user\Documents\Python\MaintenancePlannerEdition1\venv\Lib\site-packages\django\template\base.py", line 1005, in <listcomp>
    return SafeString("".join([node.render_annotated(context) for node in self]))
                               ^^^^^^^^^^^^^^^^^^^^^^^^^^^^^^
  File "C:\Users\user\Documents\Python\MaintenancePlannerEdition1\venv\Lib\site-packages\django\template\base.py", line 966, in render_annotated
    return self.render(context)
           ^^^^^^^^^^^^^^^^^^^^
  File "C:\Users\user\Documents\Python\MaintenancePlannerEdition1\venv\Lib\site-packages\django\template\defaulttags.py", line 471, in render
    url = reverse(view_name, args=args, kwargs=kwargs, current_app=current_app)
          ^^^^^^^^^^^^^^^^^^^^^^^^^^^^^^^^^^^^^^^^^^^^^^^^^^^^^^^^^^^^^^^^^^^^^
  File "C:\Users\user\Documents\Python\MaintenancePlannerEdition1\venv\Lib\site-packages\django\urls\base.py", line 88, in reverse
    return resolver._reverse_with_prefix(view, prefix, *args, **kwargs)
           ^^^^^^^^^^^^^^^^^^^^^^^^^^^^^^^^^^^^^^^^^^^^^^^^^^^^^^^^^^^^
  File "C:\Users\user\Documents\Python\MaintenancePlannerEdition1\venv\Lib\site-packages\django\urls\resolvers.py", line 828, in _reverse_with_prefix
    raise NoReverseMatch(msg)
django.urls.exceptions.NoReverseMatch: Reverse for 'password_reset_confirm' not found. 'password_reset_confirm' is not a valid view function or pattern name.
"POST /user/password-reset/ HTTP/1.1" 500 204841
Internal Server Error: /user/password-reset/confirm/Mw/set-password/
Traceback (most recent call last):
  File "C:\Users\user\Documents\Python\MaintenancePlannerEdition1\venv\Lib\site-packages\django\core\handlers\exception.py", line 55, in inner
    response = get_response(request)
               ^^^^^^^^^^^^^^^^^^^^^
  File "C:\Users\user\Documents\Python\MaintenancePlannerEdition1\venv\Lib\site-packages\django\core\handlers\base.py", line 197, in _get_response
    response = wrapped_callback(request, *callback_args, **callback_kwargs)
               ^^^^^^^^^^^^^^^^^^^^^^^^^^^^^^^^^^^^^^^^^^^^^^^^^^^^^^^^^^^^
  File "C:\Users\user\Documents\Python\MaintenancePlannerEdition1\venv\Lib\site-packages\django\views\generic\base.py", line 104, in view
    return self.dispatch(request, *args, **kwargs)
           ^^^^^^^^^^^^^^^^^^^^^^^^^^^^^^^^^^^^^^^
  File "C:\Users\user\Documents\Python\MaintenancePlannerEdition1\venv\Lib\site-packages\django\utils\decorators.py", line 46, in _wrapper
    return bound_method(*args, **kwargs)
           ^^^^^^^^^^^^^^^^^^^^^^^^^^^^^
  File "C:\Users\user\Documents\Python\MaintenancePlannerEdition1\venv\Lib\site-packages\django\views\decorators\debug.py", line 92, in sensitive_post_parameters_wrapper
    return view(request, *args, **kwargs)
           ^^^^^^^^^^^^^^^^^^^^^^^^^^^^^^
  File "C:\Users\user\Documents\Python\MaintenancePlannerEdition1\venv\Lib\site-packages\django\utils\decorators.py", line 46, in _wrapper
    return bound_method(*args, **kwargs)
           ^^^^^^^^^^^^^^^^^^^^^^^^^^^^^
  File "C:\Users\user\Documents\Python\MaintenancePlannerEdition1\venv\Lib\site-packages\django\views\decorators\cache.py", line 62, in _wrapper_view_func
    response = view_func(request, *args, **kwargs)
               ^^^^^^^^^^^^^^^^^^^^^^^^^^^^^^^^^^^
  File "C:\Users\user\Documents\Python\MaintenancePlannerEdition1\venv\Lib\site-packages\django\contrib\auth\views.py", line 295, in dispatch
    return super().dispatch(*args, **kwargs)
           ^^^^^^^^^^^^^^^^^^^^^^^^^^^^^^^^^
  File "C:\Users\user\Documents\Python\MaintenancePlannerEdition1\venv\Lib\site-packages\django\views\generic\base.py", line 143, in dispatch
    return handler(request, *args, **kwargs)
           ^^^^^^^^^^^^^^^^^^^^^^^^^^^^^^^^^
  File "C:\Users\user\Documents\Python\MaintenancePlannerEdition1\venv\Lib\site-packages\django\views\generic\edit.py", line 153, in post
    return self.form_valid(form)
           ^^^^^^^^^^^^^^^^^^^^^
  File "C:\Users\user\Documents\Python\MaintenancePlannerEdition1\venv\Lib\site-packages\django\contrib\auth\views.py", line 336, in form_valid
    return super().form_valid(form)
           ^^^^^^^^^^^^^^^^^^^^^^^^
  File "C:\Users\user\Documents\Python\MaintenancePlannerEdition1\venv\Lib\site-packages\django\views\generic\edit.py", line 65, in form_valid
    return HttpResponseRedirect(self.get_success_url())
                                ^^^^^^^^^^^^^^^^^^^^^^
  File "C:\Users\user\Documents\Python\MaintenancePlannerEdition1\venv\Lib\site-packages\django\views\generic\edit.py", line 59, in get_success_url
    if not self.success_url:
  File "C:\Users\user\Documents\Python\MaintenancePlannerEdition1\venv\Lib\site-packages\django\utils\functional.py", line 149, in __wrapper__
    res = func(*self.__args, **self.__kw)
          ^^^^^^^^^^^^^^^^^^^^^^^^^^^^^^^
  File "C:\Users\user\Documents\Python\MaintenancePlannerEdition1\venv\Lib\site-packages\django\urls\base.py", line 88, in reverse
    return resolver._reverse_with_prefix(view, prefix, *args, **kwargs)
           ^^^^^^^^^^^^^^^^^^^^^^^^^^^^^^^^^^^^^^^^^^^^^^^^^^^^^^^^^^^^
  File "C:\Users\user\Documents\Python\MaintenancePlannerEdition1\venv\Lib\site-packages\django\urls\resolvers.py", line 828, in _reverse_with_prefix
    raise NoReverseMatch(msg)
django.urls.exceptions.NoReverseMatch: Reverse for 'password_reset_complete' not found. 'password_reset_complete' is not a valid view function or pattern name.
"POST /user/password-reset/confirm/Mw/set-password/ HTTP/1.1" 500 135282
Internal Server Error: /user/password-reset/confirm/Mw/set-password/
Traceback (most recent call last):
  File "C:\Users\user\Documents\Python\MaintenancePlannerEdition1\venv\Lib\site-packages\django\core\handlers\exception.py", line 55, in inner
    response = get_response(request)
               ^^^^^^^^^^^^^^^^^^^^^
  File "C:\Users\user\Documents\Python\MaintenancePlannerEdition1\venv\Lib\site-packages\django\core\handlers\base.py", line 197, in _get_response
    response = wrapped_callback(request, *callback_args, **callback_kwargs)
               ^^^^^^^^^^^^^^^^^^^^^^^^^^^^^^^^^^^^^^^^^^^^^^^^^^^^^^^^^^^^
  File "C:\Users\user\Documents\Python\MaintenancePlannerEdition1\venv\Lib\site-packages\django\views\generic\base.py", line 104, in view
    return self.dispatch(request, *args, **kwargs)
           ^^^^^^^^^^^^^^^^^^^^^^^^^^^^^^^^^^^^^^^
  File "C:\Users\user\Documents\Python\MaintenancePlannerEdition1\venv\Lib\site-packages\django\utils\decorators.py", line 46, in _wrapper
    return bound_method(*args, **kwargs)
           ^^^^^^^^^^^^^^^^^^^^^^^^^^^^^
  File "C:\Users\user\Documents\Python\MaintenancePlannerEdition1\venv\Lib\site-packages\django\views\decorators\debug.py", line 92, in sensitive_post_parameters_wrapper
    return view(request, *args, **kwargs)
           ^^^^^^^^^^^^^^^^^^^^^^^^^^^^^^
  File "C:\Users\user\Documents\Python\MaintenancePlannerEdition1\venv\Lib\site-packages\django\utils\decorators.py", line 46, in _wrapper
    return bound_method(*args, **kwargs)
           ^^^^^^^^^^^^^^^^^^^^^^^^^^^^^
  File "C:\Users\user\Documents\Python\MaintenancePlannerEdition1\venv\Lib\site-packages\django\views\decorators\cache.py", line 62, in _wrapper_view_func
    response = view_func(request, *args, **kwargs)
               ^^^^^^^^^^^^^^^^^^^^^^^^^^^^^^^^^^^
  File "C:\Users\user\Documents\Python\MaintenancePlannerEdition1\venv\Lib\site-packages\django\contrib\auth\views.py", line 295, in dispatch
    return super().dispatch(*args, **kwargs)
           ^^^^^^^^^^^^^^^^^^^^^^^^^^^^^^^^^
  File "C:\Users\user\Documents\Python\MaintenancePlannerEdition1\venv\Lib\site-packages\django\views\generic\base.py", line 143, in dispatch
    return handler(request, *args, **kwargs)
           ^^^^^^^^^^^^^^^^^^^^^^^^^^^^^^^^^
  File "C:\Users\user\Documents\Python\MaintenancePlannerEdition1\venv\Lib\site-packages\django\views\generic\edit.py", line 153, in post
    return self.form_valid(form)
           ^^^^^^^^^^^^^^^^^^^^^
  File "C:\Users\user\Documents\Python\MaintenancePlannerEdition1\venv\Lib\site-packages\django\contrib\auth\views.py", line 336, in form_valid
    return super().form_valid(form)
           ^^^^^^^^^^^^^^^^^^^^^^^^
  File "C:\Users\user\Documents\Python\MaintenancePlannerEdition1\venv\Lib\site-packages\django\views\generic\edit.py", line 65, in form_valid
    return HttpResponseRedirect(self.get_success_url())
                                ^^^^^^^^^^^^^^^^^^^^^^
  File "C:\Users\user\Documents\Python\MaintenancePlannerEdition1\venv\Lib\site-packages\django\views\generic\edit.py", line 59, in get_success_url
    if not self.success_url:
  File "C:\Users\user\Documents\Python\MaintenancePlannerEdition1\venv\Lib\site-packages\django\utils\functional.py", line 149, in __wrapper__
    res = func(*self.__args, **self.__kw)
          ^^^^^^^^^^^^^^^^^^^^^^^^^^^^^^^
  File "C:\Users\user\Documents\Python\MaintenancePlannerEdition1\venv\Lib\site-packages\django\urls\base.py", line 88, in reverse
    return resolver._reverse_with_prefix(view, prefix, *args, **kwargs)
           ^^^^^^^^^^^^^^^^^^^^^^^^^^^^^^^^^^^^^^^^^^^^^^^^^^^^^^^^^^^^
  File "C:\Users\user\Documents\Python\MaintenancePlannerEdition1\venv\Lib\site-packages\django\urls\resolvers.py", line 828, in _reverse_with_prefix
    raise NoReverseMatch(msg)
django.urls.exceptions.NoReverseMatch: Reverse for 'password_reset_complete' not found. 'password_reset_complete' is not a valid view function or pattern name.
"POST /user/password-reset/confirm/Mw/set-password/ HTTP/1.1" 500 135262
