Internal Server Error: /plant/create/
Traceback (most recent call last):
  File "C:\Users\user\Documents\Python\MaintenancePlannerEdition1\venv\Lib\site-packages\django\core\handlers\exception.py", line 55, in inner
    response = get_response(request)
               ^^^^^^^^^^^^^^^^^^^^^
  File "C:\Users\user\Documents\Python\MaintenancePlannerEdition1\venv\Lib\site-packages\django\core\handlers\base.py", line 197, in _get_response
    response = wrapped_callback(request, *callback_args, **callback_kwargs)
               ^^^^^^^^^^^^^^^^^^^^^^^^^^^^^^^^^^^^^^^^^^^^^^^^^^^^^^^^^^^^
  File "C:\Users\user\Documents\Python\MaintenancePlannerEdition1\venv\Lib\site-packages\django\views\generic\base.py", line 104, in view
    return self.dispatch(request, *args, **kwargs)
           ^^^^^^^^^^^^^^^^^^^^^^^^^^^^^^^^^^^^^^^
  File "C:\Users\user\Documents\Python\MaintenancePlannerEdition1\venv\Lib\site-packages\django\contrib\auth\mixins.py", line 73, in dispatch
    return super().dispatch(request, *args, **kwargs)
           ^^^^^^^^^^^^^^^^^^^^^^^^^^^^^^^^^^^^^^^^^^
  File "C:\Users\user\Documents\Python\MaintenancePlannerEdition1\venv\Lib\site-packages\django\contrib\auth\mixins.py", line 107, in dispatch
    if not self.has_permission():
           ^^^^^^^^^^^^^^^^^^^^^
  File "C:\Users\user\Documents\Python\MaintenancePlannerEdition1\venv\Lib\site-packages\django\contrib\auth\mixins.py", line 103, in has_permission
    perms = self.get_permission_required()
            ^^^^^^^^^^^^^^^^^^^^^^^^^^^^^^
  File "C:\Users\user\Documents\Python\MaintenancePlannerEdition1\venv\Lib\site-packages\django\contrib\auth\mixins.py", line 87, in get_permission_required
    raise ImproperlyConfigured(
django.core.exceptions.ImproperlyConfigured: PlantCreateView is missing the permission_required attribute. Define PlantCreateView.permission_required, or override PlantCreateView.get_permission_required().
"GET /plant/create/ HTTP/1.1" 500 88302
Internal Server Error: /plant/create/
Traceback (most recent call last):
  File "C:\Users\user\Documents\Python\MaintenancePlannerEdition1\venv\Lib\site-packages\django\core\handlers\exception.py", line 55, in inner
    response = get_response(request)
               ^^^^^^^^^^^^^^^^^^^^^
  File "C:\Users\user\Documents\Python\MaintenancePlannerEdition1\venv\Lib\site-packages\django\core\handlers\base.py", line 197, in _get_response
    response = wrapped_callback(request, *callback_args, **callback_kwargs)
               ^^^^^^^^^^^^^^^^^^^^^^^^^^^^^^^^^^^^^^^^^^^^^^^^^^^^^^^^^^^^
  File "C:\Users\user\Documents\Python\MaintenancePlannerEdition1\venv\Lib\site-packages\django\views\generic\base.py", line 104, in view
    return self.dispatch(request, *args, **kwargs)
           ^^^^^^^^^^^^^^^^^^^^^^^^^^^^^^^^^^^^^^^
  File "C:\Users\user\Documents\Python\MaintenancePlannerEdition1\venv\Lib\site-packages\django\contrib\auth\mixins.py", line 73, in dispatch
    return super().dispatch(request, *args, **kwargs)
           ^^^^^^^^^^^^^^^^^^^^^^^^^^^^^^^^^^^^^^^^^^
  File "C:\Users\user\Documents\Python\MaintenancePlannerEdition1\venv\Lib\site-packages\django\contrib\auth\mixins.py", line 107, in dispatch
    if not self.has_permission():
           ^^^^^^^^^^^^^^^^^^^^^
  File "C:\Users\user\Documents\Python\MaintenancePlannerEdition1\venv\Lib\site-packages\django\contrib\auth\mixins.py", line 103, in has_permission
    perms = self.get_permission_required()
            ^^^^^^^^^^^^^^^^^^^^^^^^^^^^^^
  File "C:\Users\user\Documents\Python\MaintenancePlannerEdition1\venv\Lib\site-packages\django\contrib\auth\mixins.py", line 87, in get_permission_required
    raise ImproperlyConfigured(
django.core.exceptions.ImproperlyConfigured: PlantCreateView is missing the permission_required attribute. Define PlantCreateView.permission_required, or override PlantCreateView.get_permission_required().
"GET /plant/create/ HTTP/1.1" 500 88450
Internal Server Error: /user/delete/3/
Traceback (most recent call last):
  File "C:\Users\user\Documents\Python\MaintenancePlannerEdition1\venv\Lib\site-packages\django\core\handlers\exception.py", line 55, in inner
    response = get_response(request)
               ^^^^^^^^^^^^^^^^^^^^^
  File "C:\Users\user\Documents\Python\MaintenancePlannerEdition1\venv\Lib\site-packages\django\core\handlers\base.py", line 220, in _get_response
    response = response.render()
               ^^^^^^^^^^^^^^^^^
  File "C:\Users\user\Documents\Python\MaintenancePlannerEdition1\venv\Lib\site-packages\django\template\response.py", line 114, in render
    self.content = self.rendered_content
                   ^^^^^^^^^^^^^^^^^^^^^
  File "C:\Users\user\Documents\Python\MaintenancePlannerEdition1\venv\Lib\site-packages\django\template\response.py", line 90, in rendered_content
    template = self.resolve_template(self.template_name)
               ^^^^^^^^^^^^^^^^^^^^^^^^^^^^^^^^^^^^^^^^^
  File "C:\Users\user\Documents\Python\MaintenancePlannerEdition1\venv\Lib\site-packages\django\template\response.py", line 72, in resolve_template
    return select_template(template, using=self.using)
           ^^^^^^^^^^^^^^^^^^^^^^^^^^^^^^^^^^^^^^^^^^^
  File "C:\Users\user\Documents\Python\MaintenancePlannerEdition1\venv\Lib\site-packages\django\template\loader.py", line 47, in select_template
    raise TemplateDoesNotExist(", ".join(template_name_list), chain=chain)
django.template.exceptions.TemplateDoesNotExist: accounts/appuser_confirm_delete.html
"GET /user/delete/3/ HTTP/1.1" 500 89418
Internal Server Error: /
"GET / HTTP/1.1" 500 137
Internal Server Error: /favicon.ico
"GET /favicon.ico HTTP/1.1" 500 137
